<?xml version="1.0" encoding="UTF-8"?>
<!-- Generated by org.testng.reporters.JUnitXMLReporter -->
<testsuite hostname="apathak-MBP.local" ignored="0" tests="4" failures="1" timestamp="17 Mar 2021 07:28:56 GMT" time="0.037" errors="0">
  <testcase name="Diff" time="0.01" classname="DProvider1"/>
  <testcase name="Diff" time="0.001" classname="DProvider1"/>
  <testcase name="Sum" time="0.004" classname="DProvider1"/>
  <testcase name="Sum" time="0.001" classname="DProvider1">
    <failure type="java.lang.AssertionError" message="The following asserts failed:
	expected [10] but found [8]">
      <![CDATA[java.lang.AssertionError: The following asserts failed:
expected [10] but found [8]
at org.testng.asserts.SoftAssert.assertAll(SoftAssert.java:43)
at DProvider1.Sum(DProvider1.java:16)
at sun.reflect.NativeMethodAccessorImpl.invoke0(Native Method)
at sun.reflect.NativeMethodAccessorImpl.invoke(NativeMethodAccessorImpl.java:62)
at sun.reflect.DelegatingMethodAccessorImpl.invoke(DelegatingMethodAccessorImpl.java:43)
at java.lang.reflect.Method.invoke(Method.java:498)
at org.testng.internal.MethodInvocationHelper.invokeMethod(MethodInvocationHelper.java:124)
at org.testng.internal.InvokeMethodRunnable.runOne(InvokeMethodRunnable.java:54)
at org.testng.internal.InvokeMethodRunnable.run(InvokeMethodRunnable.java:44)
at java.util.concurrent.Executors$RunnableAdapter.call(Executors.java:511)
at java.util.concurrent.FutureTask.run(FutureTask.java:266)
at java.util.concurrent.ThreadPoolExecutor.runWorker(ThreadPoolExecutor.java:1149)
at java.util.concurrent.ThreadPoolExecutor$Worker.run(ThreadPoolExecutor.java:624)
at java.lang.Thread.run(Thread.java:748)
]]>
    </failure>
  </testcase> <!-- Sum -->
</testsuite>
